<?xml version="1.0" encoding="UTF-8"?>
<!-- Generated by org.testng.reporters.JUnitReportReporter -->
<testsuite skipped="0" hostname="asda1716po02925" name="com.qainfotech.tap.training.resourceio.TeamsYamlReaderTest" tests="10" failures="0" timestamp="04 Jul 2017 12:17:11 GMT" time="0.222" errors="2">
  <testcase name="getListOfIndividuals_should_return_array_list_of_all_individual_objects" time="0.013" classname="com.qainfotech.tap.training.resourceio.TeamsYamlReaderTest"/>
  <testcase name="getIndividualById_should_throw_ObjectNotFoundException_for_incorrect_id" time="0.002" classname="com.qainfotech.tap.training.resourceio.TeamsYamlReaderTest">
    <error type="org.testng.TestException" message="
Method TeamsYamlReaderTest.getIndividualById_should_throw_ObjectNotFoundException_for_incorrect_id()[pri:0, instance:com.qainfotech.tap.training.resourceio.TeamsYamlReaderTest@5034c75a] should have thrown an exception of type class com.qainfotech.tap.training.resourceio.exceptions.ObjectNotFoundException">
      <![CDATA[org.testng.TestException: 
Method TeamsYamlReaderTest.getIndividualById_should_throw_ObjectNotFoundException_for_incorrect_id()[pri:0, instance:com.qainfotech.tap.training.resourceio.TeamsYamlReaderTest@5034c75a] should have thrown an exception of type class com.qainfotech.tap.training.resourceio.exceptions.ObjectNotFoundException
	at org.testng.internal.ExpectedExceptionsHolder.noException(ExpectedExceptionsHolder.java:89)
	at org.testng.internal.Invoker.handleInvocationResults(Invoker.java:1416)
	at org.testng.internal.Invoker.invokeMethod(Invoker.java:695)
	at org.testng.internal.Invoker.invokeTestMethod(Invoker.java:869)
	at org.testng.internal.Invoker.invokeTestMethods(Invoker.java:1193)
	at org.testng.internal.TestMethodWorker.invokeTestMethods(TestMethodWorker.java:126)
	at org.testng.internal.TestMethodWorker.run(TestMethodWorker.java:109)
	at org.testng.TestRunner.privateRun(TestRunner.java:744)
	at org.testng.TestRunner.run(TestRunner.java:602)
	at org.testng.SuiteRunner.runTest(SuiteRunner.java:380)
	at org.testng.SuiteRunner.runSequentially(SuiteRunner.java:375)
	at org.testng.SuiteRunner.privateRun(SuiteRunner.java:340)
	at org.testng.SuiteRunner.run(SuiteRunner.java:289)
	at org.testng.SuiteRunnerWorker.runSuite(SuiteRunnerWorker.java:52)
	at org.testng.SuiteRunnerWorker.run(SuiteRunnerWorker.java:86)
	at org.testng.TestNG.runSuitesSequentially(TestNG.java:1301)
	at org.testng.TestNG.runSuitesLocally(TestNG.java:1226)
	at org.testng.TestNG.runSuites(TestNG.java:1144)
	at org.testng.TestNG.run(TestNG.java:1115)
	at org.testng.remote.AbstractRemoteTestNG.run(AbstractRemoteTestNG.java:132)
	at org.testng.remote.RemoteTestNG.initAndRun(RemoteTestNG.java:230)
	at org.testng.remote.RemoteTestNG.main(RemoteTestNG.java:76)
]]>
    </error>
  </testcase> <!-- getIndividualById_should_throw_ObjectNotFoundException_for_incorrect_id -->
  <testcase name="getIndividualByName_should_return_Individual_object_matching_name" time="0.012" classname="com.qainfotech.tap.training.resourceio.TeamsYamlReaderTest"/>
  <testcase name="getListOfInactiveIndividuals_should_return_array_list_of_only_inactive_individual_objects" time="0.004" classname="com.qainfotech.tap.training.resourceio.TeamsYamlReaderTest"/>
  <testcase name="Team_getInactiveMembers_should_return_a_list_of_individual_team_members_that_are_inactive" time="0.044" classname="com.qainfotech.tap.training.resourceio.TeamsYamlReaderTest"/>
  <testcase name="Team_getActiveMembers_should_return_a_list_of_team_members_that_are_active" time="0.100" classname="com.qainfotech.tap.training.resourceio.TeamsYamlReaderTest"/>
  <testcase name="getListOfActiveIndividuals_ahould_return_array_list_of_only_active_individual_objects" time="0.003" classname="com.qainfotech.tap.training.resourceio.TeamsYamlReaderTest"/>
  <testcase name="getListOfTeams_should_return_a_list_if_Team_object_from_db_json" time="0.034" classname="com.qainfotech.tap.training.resourceio.TeamsYamlReaderTest"/>
  <testcase name="getIndividualById_should_return_Individual_object_matching_id" time="0.008" classname="com.qainfotech.tap.training.resourceio.TeamsYamlReaderTest"/>
  <testcase name="getIndividualByName_should_throw_ObjectNotFoundException_for_incorrect_name" time="0.002" classname="com.qainfotech.tap.training.resourceio.TeamsYamlReaderTest">
    <error type="org.testng.TestException" message="
Method TeamsYamlReaderTest.getIndividualByName_should_throw_ObjectNotFoundException_for_incorrect_name()[pri:0, instance:com.qainfotech.tap.training.resourceio.TeamsYamlReaderTest@5034c75a] should have thrown an exception of type class com.qainfotech.tap.training.resourceio.exceptions.ObjectNotFoundException">
      <![CDATA[org.testng.TestException: 
Method TeamsYamlReaderTest.getIndividualByName_should_throw_ObjectNotFoundException_for_incorrect_name()[pri:0, instance:com.qainfotech.tap.training.resourceio.TeamsYamlReaderTest@5034c75a] should have thrown an exception of type class com.qainfotech.tap.training.resourceio.exceptions.ObjectNotFoundException
	at org.testng.internal.ExpectedExceptionsHolder.noException(ExpectedExceptionsHolder.java:89)
	at org.testng.internal.Invoker.handleInvocationResults(Invoker.java:1416)
	at org.testng.internal.Invoker.invokeMethod(Invoker.java:695)
	at org.testng.internal.Invoker.invokeTestMethod(Invoker.java:869)
	at org.testng.internal.Invoker.invokeTestMethods(Invoker.java:1193)
	at org.testng.internal.TestMethodWorker.invokeTestMethods(TestMethodWorker.java:126)
	at org.testng.internal.TestMethodWorker.run(TestMethodWorker.java:109)
	at org.testng.TestRunner.privateRun(TestRunner.java:744)
	at org.testng.TestRunner.run(TestRunner.java:602)
	at org.testng.SuiteRunner.runTest(SuiteRunner.java:380)
	at org.testng.SuiteRunner.runSequentially(SuiteRunner.java:375)
	at org.testng.SuiteRunner.privateRun(SuiteRunner.java:340)
	at org.testng.SuiteRunner.run(SuiteRunner.java:289)
	at org.testng.SuiteRunnerWorker.runSuite(SuiteRunnerWorker.java:52)
	at org.testng.SuiteRunnerWorker.run(SuiteRunnerWorker.java:86)
	at org.testng.TestNG.runSuitesSequentially(TestNG.java:1301)
	at org.testng.TestNG.runSuitesLocally(TestNG.java:1226)
	at org.testng.TestNG.runSuites(TestNG.java:1144)
	at org.testng.TestNG.run(TestNG.java:1115)
	at org.testng.remote.AbstractRemoteTestNG.run(AbstractRemoteTestNG.java:132)
	at org.testng.remote.RemoteTestNG.initAndRun(RemoteTestNG.java:230)
	at org.testng.remote.RemoteTestNG.main(RemoteTestNG.java:76)
]]>
    </error>
  </testcase> <!-- getIndividualByName_should_throw_ObjectNotFoundException_for_incorrect_name -->
</testsuite> <!-- com.qainfotech.tap.training.resourceio.TeamsYamlReaderTest -->
